<?xml version="1.0" encoding="UTF-8"?>
<!-- Generated by org.testng.reporters.JUnitReportReporter -->
<testsuite hostname="IdeaPad3-15IIL05" failures="1" tests="2" name="dataProvider.DataProviderExample" time="52.486" errors="0" timestamp="2023-08-19T11:36:40 IST" skipped="0">
  <testcase classname="dataProvider.DataProviderExample" name="login" time="30.621"/>
  <testcase classname="dataProvider.DataProviderExample" name="login" time="21.865">
    <failure message="Credentials is invalid expected [Logged In Successfully | Practice Test Automation] but found [Test Login | Practice Test Automation]" type="java.lang.AssertionError">
      <![CDATA[java.lang.AssertionError: Credentials is invalid expected [Logged In Successfully | Practice Test Automation] but found [Test Login | Practice Test Automation]
at org.testng.Assert.fail(Assert.java:111)
at org.testng.Assert.failNotEquals(Assert.java:1578)
at org.testng.Assert.assertEqualsImpl(Assert.java:150)
at org.testng.Assert.assertEquals(Assert.java:132)
at org.testng.Assert.assertEquals(Assert.java:656)
at dataProvider.DataProviderExample.login(DataProviderExample.java:28)
at java.base/jdk.internal.reflect.NativeMethodAccessorImpl.invoke0(Native Method)
at java.base/jdk.internal.reflect.NativeMethodAccessorImpl.invoke(NativeMethodAccessorImpl.java:77)
at java.base/jdk.internal.reflect.DelegatingMethodAccessorImpl.invoke(DelegatingMethodAccessorImpl.java:43)
at java.base/java.lang.reflect.Method.invoke(Method.java:568)
at org.testng.internal.invokers.MethodInvocationHelper.invokeMethod(MethodInvocationHelper.java:139)
at org.testng.internal.invokers.TestInvoker.invokeMethod(TestInvoker.java:664)
at org.testng.internal.invokers.TestInvoker.invokeTestMethod(TestInvoker.java:227)
at org.testng.internal.invokers.TestMethodWithDataProviderMethodWorker.call(TestMethodWithDataProviderMethodWorker.java:80)
at org.testng.internal.invokers.TestMethodWithDataProviderMethodWorker.call(TestMethodWithDataProviderMethodWorker.java:17)
at java.base/java.util.concurrent.FutureTask.run(FutureTask.java:264)
at java.base/java.util.concurrent.Executors$RunnableAdapter.call(Executors.java:539)
at java.base/java.util.concurrent.FutureTask.run(FutureTask.java:264)
at java.base/java.util.concurrent.ThreadPoolExecutor.runWorker(ThreadPoolExecutor.java:1136)
at java.base/java.util.concurrent.ThreadPoolExecutor$Worker.run(ThreadPoolExecutor.java:635)
at java.base/java.lang.Thread.run(Thread.java:833)
]]>
    </failure>
  </testcase> <!-- login -->
</testsuite> <!-- dataProvider.DataProviderExample -->
